<?xml version="1.0"?>
<!-- created with Phobos 1.0.1 "Capricious Choutengan" -->
  <robot name="Hexapod">

    <link name="L_back_coxa_link">
      <inertial>
        <origin xyz="0 0 0" rpy="0 0 0"/>
        <mass value="0.1"/>
        <inertia ixx="4e-05" ixy="1e-05" ixz="0" iyy="5e-05" iyz="0" izz="5e-05"/>
      </inertial>
      <visual name="L_back_coxa">
        <origin xyz="0 0 0" rpy="0 0 0"/>
        <geometry>
          <mesh filename="package://hexapod_description/meshes/dae/L_coxa_shape.dae" scale="1.0 1.0 1.0"/>
        </geometry>
        <material name="coxa_mat"/>
      </visual>
      <collision name="L_back_coxa">
        <origin xyz="0.0147 0.00949 0.00745" rpy="0 0 0"/>
        <geometry>
          <box size="0.05 0.05964 0.06371"/>
        </geometry>
      </collision>
    </link>

    <link name="L_back_femur_link">
      <inertial>
        <origin xyz="0 0 0" rpy="0 0 0"/>
        <mass value="0.1"/>
        <inertia ixx="0.00015" ixy="7e-05" ixz="3e-05" iyy="7e-05" iyz="-5e-05" izz="0.00022"/>
      </inertial>
      <visual name="L_back_femur">
        <origin xyz="0 0 0" rpy="3.14159 -1.5708 0"/>
        <geometry>
          <mesh filename="package://hexapod_description/meshes/dae/L_femur_shape.dae" scale="1.0 1.0 1.0"/>
        </geometry>
        <material name="femur_mat"/>
      </visual>
      <collision name="L_back_femur">
        <origin xyz="-0.02133 5e-05 0.04" rpy="3.14159 -1.5708 0"/>
        <geometry>
          <box size="0.10497 0.0249 0.002"/>
        </geometry>
      </collision>
    </link>

    <link name="L_back_foot_link">
      <inertial>
        <origin xyz="0 0 0" rpy="0 0 0"/>
        <mass value="0.001"/>
        <inertia ixx="0.001" ixy="0" ixz="0" iyy="0.001" iyz="0" izz="0.001"/>
      </inertial>
    </link>

    <link name="L_back_tibia_link">
      <inertial>
        <origin xyz="0.00047 -0.00372 -0.0585" rpy="0 0 0"/>
        <mass value="0.2"/>
        <inertia ixx="6e-05" ixy="4e-05" ixz="0" iyy="6e-05" iyz="0" izz="3e-05"/>
      </inertial>
      <visual name="L_back_foot">
        <origin xyz="0.00094 -0.00744 -0.117" rpy="0 1.5708 0"/>
        <geometry>
          <mesh filename="package://hexapod_description/meshes/dae/foot_shape.dae" scale="1.0 1.0 1.0"/>
        </geometry>
        <material name="foot_mat"/>
      </visual>
      <visual name="L_back_tibia">
        <origin xyz="0 0 0" rpy="0 1.5708 0"/>
        <geometry>
          <mesh filename="package://hexapod_description/meshes/dae/L_tibia_shape.dae" scale="1.0 1.0 1.0"/>
        </geometry>
        <material name="tibia_mat"/>
      </visual>
      <collision name="L_back_tibia.000">
        <origin xyz="0 0 0" rpy="0 1.5708 0"/>
        <geometry>
          <mesh filename="package://hexapod_description/meshes/dae/L_tibia_shape.003.dae" scale="1.0 1.0 1.0"/>
        </geometry>
      </collision>
    </link>

    <link name="L_front_coxa_link">
      <inertial>
        <origin xyz="0 0 0" rpy="0 0 0"/>
        <mass value="0.1"/>
        <inertia ixx="6e-05" ixy="0" ixz="0" iyy="3e-05" iyz="0" izz="5e-05"/>
      </inertial>
      <visual name="L_front_coxa">
        <origin xyz="0 0 0" rpy="0 0 0"/>
        <geometry>
          <mesh filename="package://hexapod_description/meshes/dae/L_coxa_shape.dae" scale="1.0 1.0 1.0"/>
        </geometry>
        <material name="coxa_mat"/>
      </visual>
      <collision name="L_front_coxa">
        <origin xyz="0.0147 0.00949 0.00745" rpy="0 0 0"/>
        <geometry>
          <box size="0.05 0.05964 0.06371"/>
        </geometry>
      </collision>
    </link>

    <link name="L_front_femur_link">
      <inertial>
        <origin xyz="0 0 0" rpy="0 0 0"/>
        <mass value="0.1"/>
        <inertia ixx="0.00016" ixy="-7e-05" ixz="-3e-05" iyy="7e-05" iyz="-5e-05" izz="0.00022"/>
      </inertial>
      <visual name="L_front_femur">
        <origin xyz="0 0 0" rpy="-3.14159 -1.5708 0"/>
        <geometry>
          <mesh filename="package://hexapod_description/meshes/dae/L_femur_shape.dae" scale="1.0 1.0 1.0"/>
        </geometry>
        <material name="femur_mat"/>
      </visual>
      <collision name="L_front_femur">
        <origin xyz="-0.02134 5e-05 0.04" rpy="-3.14159 -1.5708 0"/>
        <geometry>
          <box size="0.10497 0.0249 0.002"/>
        </geometry>
      </collision>
    </link>

    <link name="L_front_foot_link">
      <inertial>
        <origin xyz="0 0 0" rpy="0 0 0"/>
        <mass value="0.001"/>
        <inertia ixx="0.001" ixy="0" ixz="0" iyy="0.001" iyz="0" izz="0.001"/>
      </inertial>
    </link>

    <link name="L_front_tibia_link">
      <inertial>
        <origin xyz="0.00047 -0.00372 -0.0585" rpy="0 0 0"/>
        <mass value="0.2"/>
        <inertia ixx="6e-05" ixy="4e-05" ixz="0" iyy="6e-05" iyz="0" izz="3e-05"/>
      </inertial>
      <visual name="L_front_foot">
        <origin xyz="0.00094 -0.00744 -0.117" rpy="0 1.5708 0"/>
        <geometry>
          <mesh filename="package://hexapod_description/meshes/dae/foot_shape.dae" scale="1.0 1.0 1.0"/>
        </geometry>
        <material name="foot_mat"/>
      </visual>
      <visual name="L_front_tibia">
        <origin xyz="0 0 0" rpy="0 1.5708 0"/>
        <geometry>
          <mesh filename="package://hexapod_description/meshes/dae/L_tibia_shape.dae" scale="1.0 1.0 1.0"/>
        </geometry>
        <material name="tibia_mat"/>
      </visual>
      <collision name="L_front_tibia.000">
        <origin xyz="0 0 0" rpy="0 1.5708 0"/>
        <geometry>
          <mesh filename="package://hexapod_description/meshes/dae/L_tibia_shape.001.dae" scale="1.0 1.0 1.0"/>
        </geometry>
      </collision>
    </link>

    <link name="L_mid_coxa_link">
      <inertial>
        <origin xyz="0 0 0" rpy="0 0 0"/>
        <mass value="0.1"/>
        <inertia ixx="5e-05" ixy="0" ixz="0" iyy="3e-05" iyz="0" izz="5e-05"/>
      </inertial>
      <visual name="L_mid_coxa">
        <origin xyz="0 0 0" rpy="0 0 0"/>
        <geometry>
          <mesh filename="package://hexapod_description/meshes/dae/L_coxa_shape.dae" scale="1.0 1.0 1.0"/>
        </geometry>
        <material name="coxa_mat"/>
      </visual>
      <collision name="L_mid_coxa">
        <origin xyz="0.0147 0.00949 0.00745" rpy="0 0 0"/>
        <geometry>
          <box size="0.05 0.05964 0.06371"/>
        </geometry>
      </collision>
    </link>

    <link name="L_mid_femur_link">
      <inertial>
        <origin xyz="0 0 0" rpy="0 0 0"/>
        <mass value="0.1"/>
        <inertia ixx="0.00019" ixy="0" ixz="0" iyy="3e-05" iyz="-6e-05" izz="0.00022"/>
      </inertial>
      <visual name="L_mid_femur">
        <origin xyz="0 0 0" rpy="-3.14159 -1.5708 0"/>
        <geometry>
          <mesh filename="package://hexapod_description/meshes/dae/L_femur_shape.dae" scale="1.0 1.0 1.0"/>
        </geometry>
        <material name="femur_mat"/>
      </visual>
      <collision name="L_mid_femur">
        <origin xyz="-0.02134 5e-05 0.04" rpy="-3.14159 -1.5708 0"/>
        <geometry>
          <box size="0.10497 0.0249 0.002"/>
        </geometry>
      </collision>
    </link>

    <link name="L_mid_foot_link">
      <inertial>
        <origin xyz="0 0 0" rpy="0 0 0"/>
        <mass value="0.001"/>
        <inertia ixx="0.001" ixy="0" ixz="0" iyy="0.001" iyz="0" izz="0.001"/>
      </inertial>
    </link>

    <link name="L_mid_tibia_link">
      <inertial>
        <origin xyz="0.00047 -0.00372 -0.0585" rpy="0 0 0"/>
        <mass value="0.2"/>
        <inertia ixx="6e-05" ixy="4e-05" ixz="0" iyy="7e-05" iyz="0" izz="3e-05"/>
      </inertial>
      <visual name="L_mid_foot">
        <origin xyz="0.00094 -0.00744 -0.117" rpy="0 1.5708 0"/>
        <geometry>
          <mesh filename="package://hexapod_description/meshes/dae/foot_shape.dae" scale="1.0 1.0 1.0"/>
        </geometry>
        <material name="foot_mat"/>
      </visual>
      <visual name="L_mid_tibia">
        <origin xyz="0 0 0" rpy="0 1.5708 0"/>
        <geometry>
          <mesh filename="package://hexapod_description/meshes/dae/L_tibia_shape.dae" scale="1.0 1.0 1.0"/>
        </geometry>
        <material name="tibia_mat"/>
      </visual>
      <collision name="L_mid_tibia.000">
        <origin xyz="0 0 0" rpy="0 1.5708 0"/>
        <geometry>
          <mesh filename="package://hexapod_description/meshes/dae/L_tibia_shape.002.dae" scale="1.0 1.0 1.0"/>
        </geometry>
      </collision>
    </link>

    <link name="R_back_coxa_link">
      <inertial>
        <origin xyz="0 0 0" rpy="0 0 0"/>
        <mass value="0.1"/>
        <inertia ixx="6e-05" ixy="0" ixz="0" iyy="3e-05" iyz="0" izz="5e-05"/>
      </inertial>
      <visual name="R_back_coxa">
        <origin xyz="0 0 0" rpy="0 0 0"/>
        <geometry>
          <mesh filename="package://hexapod_description/meshes/dae/R_coxa_shape.dae" scale="1.0 1.0 1.0"/>
        </geometry>
        <material name="coxa_mat"/>
      </visual>
      <collision name="R_back_coxa">
        <origin xyz="0.0147 -0.00949 0.00745" rpy="0 0 0"/>
        <geometry>
          <box size="0.05 0.05964 0.06371"/>
        </geometry>
      </collision>
    </link>

    <link name="R_back_femur_link">
      <inertial>
        <origin xyz="0 0 0" rpy="0 0 0"/>
        <mass value="0.1"/>
        <inertia ixx="0.00016" ixy="-7e-05" ixz="-3e-05" iyy="7e-05" iyz="-5e-05" izz="0.00022"/>
      </inertial>
      <visual name="R_back_femur">
        <origin xyz="0 0 0" rpy="3.14159 -1.5708 0"/>
        <geometry>
          <mesh filename="package://hexapod_description/meshes/dae/R_femur_shape.dae" scale="1.0 1.0 1.0"/>
        </geometry>
        <material name="femur_mat"/>
      </visual>
      <collision name="R_back_femur">
        <origin xyz="0.02134 5e-05 0.04" rpy="3.14159 -1.5708 0"/>
        <geometry>
          <box size="0.10497 0.0249 0.002"/>
        </geometry>
      </collision>
    </link>

    <link name="R_back_foot_link">
      <inertial>
        <origin xyz="0 0 0" rpy="0 0 0"/>
        <mass value="0.001"/>
        <inertia ixx="0.001" ixy="0" ixz="0" iyy="0.001" iyz="0" izz="0.001"/>
      </inertial>
    </link>

    <link name="R_back_tibia_link">
      <inertial>
        <origin xyz="-0.00049 -0.0037 -0.0585" rpy="0 0 0"/>
        <mass value="0.2"/>
        <inertia ixx="6e-05" ixy="4e-05" ixz="0" iyy="6e-05" iyz="-1e-05" izz="3e-05"/>
      </inertial>
      <visual name="R_back_foot">
        <origin xyz="-0.00099 -0.0074 -0.117" rpy="0 1.5708 0"/>
        <geometry>
          <mesh filename="package://hexapod_description/meshes/dae/foot_shape.dae" scale="1.0 1.0 1.0"/>
        </geometry>
        <material name="foot_mat"/>
      </visual>
      <visual name="R_back_tibia">
        <origin xyz="0 0 0" rpy="0 1.5708 0"/>
        <geometry>
          <mesh filename="package://hexapod_description/meshes/dae/R_tibia_shape.dae" scale="1.0 1.0 1.0"/>
        </geometry>
        <material name="tibia_mat"/>
      </visual>
      <collision name="R_back_tibia.000">
        <origin xyz="0 0 0" rpy="0 1.5708 0"/>
        <geometry>
          <mesh filename="package://hexapod_description/meshes/dae/R_tibia_shape.002.dae" scale="1.0 1.0 1.0"/>
        </geometry>
      </collision>
    </link>

    <link name="R_front_coxa_link">
      <inertial>
        <origin xyz="0 0 0" rpy="0 0 0"/>
        <mass value="0.1"/>
        <inertia ixx="4e-05" ixy="0" ixz="1e-05" iyy="5e-05" iyz="0" izz="5e-05"/>
      </inertial>
      <visual name="R_front_coxa">
        <origin xyz="0 0 0" rpy="0 0 0"/>
        <geometry>
          <mesh filename="package://hexapod_description/meshes/dae/R_coxa_shape.dae" scale="1.0 1.0 1.0"/>
        </geometry>
        <material name="coxa_mat"/>
      </visual>
      <collision name="R_front_coxa">
        <origin xyz="0.0147 -0.00949 0.00745" rpy="0 0 0"/>
        <geometry>
          <box size="0.05 0.05964 0.06371"/>
        </geometry>
      </collision>
    </link>

    <link name="R_front_femur_link">
      <inertial>
        <origin xyz="0 0 0" rpy="0 0 0"/>
        <mass value="0.1"/>
        <inertia ixx="0.00015" ixy="7e-05" ixz="3e-05" iyy="7e-05" iyz="-5e-05" izz="0.00022"/>
      </inertial>
      <visual name="R_front_femur">
        <origin xyz="0 0 0" rpy="3.14159 -1.5708 0"/>
        <geometry>
          <mesh filename="package://hexapod_description/meshes/dae/R_femur_shape.dae" scale="1.0 1.0 1.0"/>
        </geometry>
        <material name="femur_mat"/>
      </visual>
      <collision name="R_front_femur">
        <origin xyz="0.02133 5e-05 0.04" rpy="3.14159 -1.5708 0"/>
        <geometry>
          <box size="0.10497 0.0249 0.002"/>
        </geometry>
      </collision>
    </link>

    <link name="R_front_foot_link">
      <inertial>
        <origin xyz="0 0 0" rpy="0 0 0"/>
        <mass value="0.001"/>
        <inertia ixx="0.001" ixy="0" ixz="0" iyy="0.001" iyz="0" izz="0.001"/>
      </inertial>
    </link>

    <link name="R_front_tibia_link">
      <inertial>
        <origin xyz="-0.00049 -0.0037 -0.0585" rpy="0 0 0"/>
        <mass value="0.2"/>
        <inertia ixx="6e-05" ixy="4e-05" ixz="0" iyy="6e-05" iyz="0" izz="3e-05"/>
      </inertial>
      <visual name="R_front_foot">
        <origin xyz="-0.00099 -0.0074 -0.117" rpy="0 1.5708 0"/>
        <geometry>
          <mesh filename="package://hexapod_description/meshes/dae/foot_shape.dae" scale="1.0 1.0 1.0"/>
        </geometry>
        <material name="foot_mat"/>
      </visual>
      <visual name="R_front_tibia">
        <origin xyz="0 0 0" rpy="0 1.5708 0"/>
        <geometry>
          <mesh filename="package://hexapod_description/meshes/dae/R_tibia_shape.dae" scale="1.0 1.0 1.0"/>
        </geometry>
        <material name="tibia_mat"/>
      </visual>
      <collision name="R_front_tibia.000">
        <origin xyz="0 0 0" rpy="0 1.5708 0"/>
        <geometry>
          <mesh filename="package://hexapod_description/meshes/dae/R_tibia_shape.001.dae" scale="1.0 1.0 1.0"/>
        </geometry>
      </collision>
    </link>

    <link name="R_mid_coxa_link">
      <inertial>
        <origin xyz="0 0 0" rpy="0 0 0"/>
        <mass value="0.1"/>
        <inertia ixx="5e-05" ixy="0" ixz="0" iyy="3e-05" iyz="0" izz="5e-05"/>
      </inertial>
      <visual name="R_mid_coxa">
        <origin xyz="0 0 0" rpy="0 0 0"/>
        <geometry>
          <mesh filename="package://hexapod_description/meshes/dae/R_coxa_shape.dae" scale="1.0 1.0 1.0"/>
        </geometry>
        <material name="coxa_mat"/>
      </visual>
      <collision name="R_mid_coxa">
        <origin xyz="0.0147 -0.00949 0.00745" rpy="0 0 0"/>
        <geometry>
          <box size="0.05 0.05964 0.06371"/>
        </geometry>
      </collision>
    </link>

    <link name="R_mid_femur_link">
      <inertial>
        <origin xyz="0 0 0" rpy="0 0 0"/>
        <mass value="0.1"/>
        <inertia ixx="0.00019" ixy="0" ixz="0" iyy="3e-05" iyz="-6e-05" izz="0.00022"/>
      </inertial>
      <visual name="R_mid_femur">
        <origin xyz="0 0 0" rpy="-3.14159 -1.5708 0"/>
        <geometry>
          <mesh filename="package://hexapod_description/meshes/dae/R_femur_shape.dae" scale="1.0 1.0 1.0"/>
        </geometry>
        <material name="femur_mat"/>
      </visual>
      <collision name="R_mid_femur">
        <origin xyz="0.02134 5e-05 0.04" rpy="-3.14159 -1.5708 0"/>
        <geometry>
          <box size="0.10497 0.0249 0.002"/>
        </geometry>
      </collision>
    </link>

    <link name="R_mid_foot_link">
      <inertial>
        <origin xyz="0 0 0" rpy="0 0 0"/>
        <mass value="0.001"/>
        <inertia ixx="0.001" ixy="0" ixz="0" iyy="0.001" iyz="0" izz="0.001"/>
      </inertial>
    </link>

    <link name="R_mid_tibia_link">
      <inertial>
        <origin xyz="-0.00049 -0.0037 -0.0585" rpy="0 0 0"/>
        <mass value="0.2"/>
        <inertia ixx="6e-05" ixy="4e-05" ixz="0" iyy="7e-05" iyz="-1e-05" izz="3e-05"/>
      </inertial>
      <visual name="R_mid_foot">
        <origin xyz="-0.00099 -0.0074 -0.117" rpy="0 1.5708 0"/>
        <geometry>
          <mesh filename="package://hexapod_description/meshes/dae/foot_shape.dae" scale="1.0 1.0 1.0"/>
        </geometry>
        <material name="foot_mat"/>
      </visual>
      <visual name="R_mid_tibia">
        <origin xyz="0 0 0" rpy="0 1.5708 0"/>
        <geometry>
          <mesh filename="package://hexapod_description/meshes/dae/R_tibia_shape.dae" scale="1.0 1.0 1.0"/>
        </geometry>
        <material name="tibia_mat"/>
      </visual>
      <collision name="R_mid_tibia.000">
        <origin xyz="0 0 0" rpy="0 1.5708 0"/>
        <geometry>
          <mesh filename="package://hexapod_description/meshes/dae/R_tibia_shape.003.dae" scale="1.0 1.0 1.0"/>
        </geometry>
      </collision>
    </link>

    <link name="body_link">
      <inertial>
        <origin xyz="0 0 0" rpy="0 0 0"/>
        <mass value="0.2"/>
        <inertia ixx="0.00024" ixy="0" ixz="0" iyy="0.00047" iyz="0" izz="0.00055"/>
      </inertial>
      <visual name="thorax">
        <origin xyz="0 0 0" rpy="0 0 0"/>
        <geometry>
          <mesh filename="package://hexapod_description/meshes/dae/thorax_shape.dae" scale="1.0 1.0 1.0"/>
        </geometry>
        <material name="thorax_mat"/>
      </visual>
      <collision name="thorax">
        <origin xyz="0 0 0.00135" rpy="0 0 0"/>
        <geometry>
          <box size="0.20038 0.1651 0.0538"/>
        </geometry>
      </collision>
    </link>

    <link name="root_link" />

    <joint name="L_back_coxa_jnt" type="revolute">
      <origin xyz="-0.0876 0.05057 0" rpy="0 0 2.0944"/>
      <parent link="body_link"/>
      <child link="L_back_coxa_link"/>
      <axis xyz="0 0 -1.0"/>
      <limit lower="-1.5708" upper="1.5708" effort="1.274" velocity="3e-05"/>
    </joint>

    <joint name="L_back_femur_jnt" type="revolute">
      <origin xyz="0.0294 0 0" rpy="1.5708 0 1.5708"/>
      <parent link="L_back_coxa_link"/>
      <child link="L_back_femur_link"/>
      <axis xyz="1.0 0 0"/>
      <limit lower="-1.5708" upper="1.5708" effort="1.274" velocity="3e-05"/>
    </joint>

    <joint name="L_back_foot_jnt" type="fixed">
      <origin xyz="0 -0.0075 -0.117" rpy="0 0 0"/> <!-- <origin xyz="-0.13777 0.13934 -0.117" rpy="0 0 2.0944"/> -->
      <parent link="L_back_tibia_link"/>
      <child link="L_back_foot_link"/>
      <limit effort="1.274" velocity="3e-05"/>
    </joint>

    <joint name="L_back_tibia_jnt" type="revolute">
      <origin xyz="0 0 0.08" rpy="1.5708 0 3.14159"/>
      <parent link="L_back_femur_link"/>
      <child link="L_back_tibia_link"/>
      <axis xyz="-1.0 0 0"/>
      <limit lower="-1.5708" upper="1.5708" effort="1.274" velocity="3e-05"/>
    </joint>

    <joint name="L_front_coxa_jnt" type="revolute">
      <origin xyz="0.0876 0.05057 0" rpy="0 0 1.0472"/>
      <parent link="body_link"/>
      <child link="L_front_coxa_link"/>
      <axis xyz="0 0 -1.0"/>
      <limit lower="-1.5708" upper="1.5708" effort="1.274" velocity="3e-05"/>
    </joint>

    <joint name="L_front_femur_jnt" type="revolute">
      <origin xyz="0.0294 0 0" rpy="1.5708 0 1.5708"/>
      <parent link="L_front_coxa_link"/>
      <child link="L_front_femur_link"/>
      <axis xyz="1.0 0 0"/>
      <limit lower="-1.5708" upper="1.5708" effort="1.274" velocity="3e-05"/>
    </joint>

    <joint name="L_front_foot_jnt" type="fixed">
      <origin xyz="0 -0.0075 -0.117" rpy="0 0 0"/> <!-- <origin xyz="0.13939 0.1384 -0.117" rpy="0 0 1.0472"/> -->
      <parent link="L_front_tibia_link"/>
      <child link="L_front_foot_link"/>
      <limit effort="1.274" velocity="3e-05"/>
    </joint>

    <joint name="L_front_tibia_jnt" type="revolute">
      <origin xyz="0 0 0.08" rpy="-1.5708 3.14159 0"/>
      <parent link="L_front_femur_link"/>
      <child link="L_front_tibia_link"/>
      <axis xyz="-1.0 0 0"/>
      <limit lower="-1.5708" upper="1.5708" effort="1.274" velocity="3e-05"/>
    </joint>

    <joint name="L_mid_coxa_jnt" type="revolute">
      <origin xyz="0 0.06985 0" rpy="0 0 1.5708"/>
      <parent link="body_link"/>
      <child link="L_mid_coxa_link"/>
      <axis xyz="0 0 -1.0"/>
      <limit lower="-1.5708" upper="1.5708" effort="1.274" velocity="3e-05"/>
    </joint>

    <joint name="L_mid_femur_jnt" type="revolute">
      <origin xyz="0.0294 0 0" rpy="1.5708 0 1.5708"/>
      <parent link="L_mid_coxa_link"/>
      <child link="L_mid_femur_link"/>
      <axis xyz="1.0 0 0"/>
      <limit lower="-1.5708" upper="1.5708" effort="1.274" velocity="3e-05"/>
    </joint>

    <joint name="L_mid_foot_jnt" type="fixed">
      <origin xyz="0 -0.0075 -0.117" rpy="0 0 0"/> <!-- <origin xyz="0.00094 0.17181 -0.117" rpy="0 0 1.5708"/> -->
      <parent link="L_mid_tibia_link"/>
      <child link="L_mid_foot_link"/>
      <limit effort="1.274" velocity="3e-05"/>
    </joint>

    <joint name="L_mid_tibia_jnt" type="revolute">
      <origin xyz="0 0 0.08" rpy="1.5708 0 -3.14159"/>
      <parent link="L_mid_femur_link"/>
      <child link="L_mid_tibia_link"/>
      <axis xyz="-1.0 0 0"/>
      <limit lower="-1.5708" upper="1.5708" effort="1.274" velocity="3e-05"/>
    </joint>

    <joint name="R_back_coxa_jnt" type="revolute">
      <origin xyz="-0.0876 -0.05057 0" rpy="0 0 -2.0944"/>
      <parent link="body_link"/>
      <child link="R_back_coxa_link"/>
      <axis xyz="0 0 1.0"/>
      <limit lower="-1.5708" upper="1.5708" effort="1.274" velocity="3e-05"/>
    </joint>

    <joint name="R_back_femur_jnt" type="revolute">
      <origin xyz="0.0294 0 0" rpy="1.5708 0 1.5708"/>
      <parent link="R_back_coxa_link"/>
      <child link="R_back_femur_link"/>
      <axis xyz="1.0 0 0"/>
      <limit lower="-1.5708" upper="1.5708" effort="1.274" velocity="3e-05"/>
    </joint>

    <joint name="R_back_foot_jnt" type="fixed">
      <origin xyz="0 -0.0075 -0.117" rpy="0 0 0"/> <!-- <origin xyz="-0.13774 -0.1394 -0.117" rpy="0 0 -2.09439"/> -->
      <parent link="R_back_tibia_link"/>
      <child link="R_back_foot_link"/>
      <limit effort="1.274" velocity="3e-05"/>
    </joint>

    <joint name="R_back_tibia_jnt" type="revolute">
      <origin xyz="0 0 0.08" rpy="1.5708 0 3.14159"/>
      <parent link="R_back_femur_link"/>
      <child link="R_back_tibia_link"/>
      <axis xyz="-1.0 0 0"/>
      <limit lower="-1.5708" upper="1.5708" effort="1.274" velocity="3e-05"/>
    </joint>

    <joint name="R_front_coxa_jnt" type="revolute">
      <origin xyz="0.0876 -0.05057 0" rpy="0 0 -1.0472"/>
      <parent link="body_link"/>
      <child link="R_front_coxa_link"/>
      <axis xyz="0 0 1.0"/>
      <limit lower="-1.5708" upper="1.5708" effort="1.274" velocity="3e-05"/>
    </joint>

    <joint name="R_front_femur_jnt" type="revolute">
      <origin xyz="0.0294 0 0" rpy="1.5708 0 1.5708"/>
      <parent link="R_front_coxa_link"/>
      <child link="R_front_femur_link"/>
      <axis xyz="1.0 0 0"/>
      <limit lower="-1.5708" upper="1.5708" effort="1.274" velocity="3e-05"/>
    </joint>

    <joint name="R_front_foot_jnt" type="fixed">
      <origin xyz="0 -0.0075 -0.117" rpy="0 0 0"/> <!-- <origin xyz="0.13945 -0.13842 -0.117" rpy="0 0 -1.0472"/> -->
      <parent link="R_front_tibia_link"/>
      <child link="R_front_foot_link"/>
      <limit effort="1.274" velocity="3e-05"/>
    </joint>

    <joint name="R_front_tibia_jnt" type="revolute">
      <origin xyz="0 0 0.08" rpy="1.5708 0 3.14159"/>
      <parent link="R_front_femur_link"/>
      <child link="R_front_tibia_link"/>
      <axis xyz="-1.0 0 0"/>
      <limit lower="-1.5708" upper="1.5708" effort="1.274" velocity="3e-05"/>
    </joint>

    <joint name="R_mid_coxa_jnt" type="revolute">
      <origin xyz="0 -0.06985 0" rpy="0 0 -1.5708"/>
      <parent link="body_link"/>
      <child link="R_mid_coxa_link"/>
      <axis xyz="0 0 1.0"/>
      <limit lower="-1.5708" upper="1.5708" effort="1.274" velocity="3e-05"/>
    </joint>

    <joint name="R_mid_femur_jnt" type="revolute">
      <origin xyz="0.0294 0 0" rpy="1.5708 0 1.5708"/>
      <parent link="R_mid_coxa_link"/>
      <child link="R_mid_femur_link"/>
      <axis xyz="1.0 0 0"/>
      <limit lower="-1.5708" upper="1.5708" effort="1.274" velocity="3e-05"/>
    </joint>

    <joint name="R_mid_foot_jnt" type="fixed">
      <origin xyz="0 -0.0075 -0.117" rpy="0 0 0"/> <!-- <origin xyz="0.00099 -0.17185 -0.117" rpy="0 0 -1.5708"/> -->
      <parent link="R_mid_tibia_link"/>
      <child link="R_mid_foot_link"/>
      <limit effort="1.274" velocity="3e-05"/>
    </joint>

    <joint name="R_mid_tibia_jnt" type="revolute">
      <origin xyz="0 0 0.08" rpy="1.5708 0 3.14159"/>
      <parent link="R_mid_femur_link"/>
      <child link="R_mid_tibia_link"/>
      <axis xyz="-1.0 0 0"/>
      <limit lower="-1.5708" upper="1.5708" effort="1.274" velocity="3e-05"/>
    </joint>

    <joint name="body_jnt" type="fixed">
      <origin xyz="0 0 0" rpy="0 0 0"/>
      <parent link="root_link"/>
      <child link="body_link"/>
      <limit effort="1.274" velocity="3e-05"/>
    </joint>

    <link name="L_front_ee_link" />
    <link name="L_mid_ee_link" />
    <link name="L_back_ee_link" />
    <link name="R_front_ee_link" />
    <link name="R_mid_ee_link" />
    <link name="R_back_ee_link" />

    <joint name="L_front_ee_jnt" type="fixed">
      <origin xyz="0 0 0" rpy="0 0 0"/>
      <parent link="L_front_foot_link"/>
      <child link="L_front_ee_link"/>
    </joint>
    <joint name="L_mid_ee_jnt" type="fixed">
      <origin xyz="0 0 0" rpy="0 0 0"/>
      <parent link="L_mid_foot_link"/>
      <child link="L_mid_ee_link"/>
    </joint>
    <joint name="L_back_ee_jnt" type="fixed">
      <origin xyz="0 0 0" rpy="0 0 0"/>
      <parent link="L_back_foot_link"/>
      <child link="L_back_ee_link"/>
    </joint>
    <joint name="R_front_ee_jnt" type="fixed">
      <origin xyz="0 0 0" rpy="0 0 0"/>
      <parent link="R_front_foot_link"/>
      <child link="R_front_ee_link"/>
    </joint>
    <joint name="R_mid_ee_jnt" type="fixed">
      <origin xyz="0 0 0" rpy="0 0 0"/>
      <parent link="R_mid_foot_link"/>
      <child link="R_mid_ee_link"/>
    </joint>
    <joint name="R_back_ee_jnt" type="fixed">
      <origin xyz="0 0 0" rpy="0 0 0"/>
      <parent link="R_back_foot_link"/>
      <child link="R_back_ee_link"/>
    </joint>

    <material name="coxa_mat">
      <color rgba="0.64 0.64 0.64 1.0"/>
    </material>

    <material name="femur_mat">
      <color rgba="0.64 0.64 0.64 1.0"/>
    </material>

    <material name="foot_mat">
      <color rgba="0.64 0.64 0.64 1.0"/>
    </material>

    <material name="thorax_mat">
      <color rgba="0.64 0.64 0.64 1.0"/>
    </material>

    <material name="tibia_mat">
      <color rgba="0.64 0.64 0.64 1.0"/>
    </material>

  </robot>
